[1m[31mERROR   [0m asyncio:base_events.py:1758 Task was destroyed but it is pending!
task: <Task pending name='Task-54' coro=<WebSocketCommonProtocol.keepalive_ping() running at /home/runner/work/indico-operator/indico-operator/.tox/integration/lib/python3.10/site-packages/websockets/legacy/protocol.py:1242> wait_for=<Future pending cb=[Task.task_wakeup()]>>
[1m[31mERROR   [0m asyncio:base_events.py:1758 Task was destroyed but it is pending!
task: <Task pending name='Task-61' coro=<Connection._pinger() running at /home/runner/work/indico-operator/indico-operator/.tox/integration/lib/python3.10/site-packages/juju/client/connection.py:579> wait_for=<Future pending cb=[Task.task_wakeup()]>>
[1m[31mERROR   [0m asyncio:base_events.py:1758 Fatal error on SSL transport
protocol: <asyncio.sslproto.SSLProtocol object at 0x7f8d97bd3be0>
transport: <_SelectorSocketTransport closing fd=19>
Traceback (most recent call last):
  File "/usr/lib/python3.10/asyncio/selector_events.py", line 924, in write
    n = self._sock.send(data)
OSError: [Errno 9] Bad file descriptor

During handling of the above exception, another exception occurred:

Traceback (most recent call last):
  File "/usr/lib/python3.10/asyncio/sslproto.py", line 690, in _process_write_backlog
    self._transport.write(chunk)
  File "/usr/lib/python3.10/asyncio/selector_events.py", line 930, in write
    self._fatal_error(exc, 'Fatal write error on socket transport')
  File "/usr/lib/python3.10/asyncio/selector_events.py", line 725, in _fatal_error
    self._force_close(exc)
  File "/usr/lib/python3.10/asyncio/selector_events.py", line 737, in _force_close
    self._loop.call_soon(self._call_connection_lost, exc)
  File "/usr/lib/python3.10/asyncio/base_events.py", line 753, in call_soon
    self._check_closed()
  File "/usr/lib/python3.10/asyncio/base_events.py", line 515, in _check_closed
    raise RuntimeError('Event loop is closed')
RuntimeError: Event loop is closed
[1m[31mERROR   [0m asyncio:base_events.py:1758 Task was destroyed but it is pending!
task: <Task pending name='Task-53' coro=<WebSocketCommonProtocol.transfer_data() running at /home/runner/work/indico-operator/indico-operator/.tox/integration/lib/python3.10/site-packages/websockets/legacy/protocol.py:953> wait_for=<Future pending cb=[Task.task_wakeup()]> cb=[Task.task_wakeup(), _wait.<locals>._on_completion() at /usr/lib/python3.10/asyncio/tasks.py:475]>
[1m[31mERROR   [0m asyncio:base_events.py:1758 Task was destroyed but it is pending!
task: <Task pending name='Task-55' coro=<WebSocketCommonProtocol.close_connection() running at /home/runner/work/indico-operator/indico-operator/.tox/integration/lib/python3.10/site-packages/websockets/legacy/protocol.py:1287> wait_for=<Task pending name='Task-53' coro=<WebSocketCommonProtocol.transfer_data() running at /home/runner/work/indico-operator/indico-operator/.tox/integration/lib/python3.10/site-packages/websockets/legacy/protocol.py:953> wait_for=<Future pending cb=[Task.task_wakeup()]> cb=[Task.task_wakeup(), _wait.<locals>._on_completion() at /usr/lib/python3.10/asyncio/tasks.py:475]>>
[1m[31mERROR   [0m asyncio:base_events.py:1758 Task was destroyed but it is pending!
task: <Task pending name='Task-56' coro=<Connection._receiver() running at /home/runner/work/indico-operator/indico-operator/.tox/integration/lib/python3.10/site-packages/juju/client/connection.py:531> wait_for=<Future pending cb=[Task.task_wakeup()]>>
[1m[31mERROR   [0m asyncio:base_events.py:1758 Task was destroyed but it is pending!
task: <Task pending name='Task-4809' coro=<WebSocketCommonProtocol.recv() running at /home/runner/work/indico-operator/indico-operator/.tox/integration/lib/python3.10/site-packages/websockets/legacy/protocol.py:546> wait_for=<Future pending cb=[Task.task_wakeup()]> cb=[create_task_with_handler.<locals>._task_result_exp_handler(task_name='tmp', logger=<Logger juju....ection (INFO)>)() at /home/runner/work/indico-operator/indico-operator/.tox/integration/lib/python3.10/site-packages/juju/jasyncio.py:53]>
[1m[31mERROR   [0m asyncio:base_events.py:1758 Task was destroyed but it is pending!
task: <Task pending name='Task-4810' coro=<Event.wait() running at /usr/lib/python3.10/asyncio/locks.py:214> wait_for=<Future pending cb=[Task.task_wakeup()]>>
[33mWARNING [0m charms.prometheus_k8s.v0.prometheus_scrape:prometheus_scrape.py:1452 2 containers are present in metadata.yaml and refresh_event was not specified. Defaulting to update_status. Metrics IP may not be set in a timely fashion.